<mujoco model="nix1">
  <compiler angle="radian" meshdir="../meshes/"/>

  <default>
      <default class="nix1">
          <geom friction="0.5" margin="0.001"/>
          <joint type="hinge" damping="1" armature="0.1" frictionloss="0.2" limited="true"/>
          <motor ctrlrange="-200 200" />
          <default class="visual">
              <geom type="mesh" contype="0" conaffinity="0" group="2" material="dark"/>
          </default>
          <default class="collision">
              <geom group="0" type="capsule" mass="0" density="0" />
              <default class="foot">
                  <geom type="sphere" priority="1" solimp="0.015 1 0.031" condim="6"  friction="0.8 0.02 0.01" size="0.025" pos="0.019 0 -0.105" quat="1 0 0 0" rgba="0.189804 0.176471 0.129412 1" />
              </default>
          </default>
          <site size="0.001" rgba="0.5 0.5 0.5 0.3" group="4"/>
      </default>
  </default>

  <asset>
    <mesh name="pelvis" file="pelvis.STL"/>
    <mesh name="left_hip_pitch_link" file="left_hip_pitch_link.STL"/>
    <mesh name="left_hip_roll_link" file="left_hip_roll_link.STL"/>
    <mesh name="left_hip_yaw_link" file="left_hip_yaw_link.STL"/>
    <mesh name="left_knee_link" file="left_knee_link.STL"/>
    <mesh name="left_ankle_pitch_link" file="left_ankle_pitch_link.STL"/>
    <mesh name="left_ankle_roll_link" file="left_ankle_roll_link.STL"/>
    <mesh name="right_hip_pitch_link" file="right_hip_pitch_link.STL"/>
    <mesh name="right_hip_roll_link" file="right_hip_roll_link.STL"/>
    <mesh name="right_hip_yaw_link" file="right_hip_yaw_link.STL"/>
    <mesh name="right_knee_link" file="right_knee_link.STL"/>
    <mesh name="right_ankle_pitch_link" file="right_ankle_pitch_link.STL"/>
    <mesh name="right_ankle_roll_link" file="right_ankle_roll_link.STL"/>
    <mesh name="torso_link" file="torso_link.STL"/>
    <mesh name="left_shoulder_pitch_link" file="left_shoulder_pitch_link.STL"/>
    <mesh name="left_shoulder_roll_link" file="left_shoulder_roll_link.STL"/>
    <mesh name="left_shoulder_yaw_link" file="left_shoulder_yaw_link.STL"/>
    <mesh name="left_elbow_link" file="left_elbow_link.STL"/>
    <mesh name="right_shoulder_pitch_link" file="right_shoulder_pitch_link.STL"/>
    <mesh name="right_shoulder_roll_link" file="right_shoulder_roll_link.STL"/>
    <mesh name="right_shoulder_yaw_link" file="right_shoulder_yaw_link.STL"/>
    <mesh name="right_elbow_link" file="right_elbow_link.STL"/>
    <texture name="texplane" type="2d" builtin="checker" rgb1=".2 .3 .4" rgb2=".1 0.15 0.2" width="100" height="100"/>
    <material name="MatPlane" reflectance="0.5" texture="texplane" texrepeat="1 1" texuniform="true"/>
  </asset>

  <worldbody>

    <geom name="floor" friction="1 .1 .1" pos="0 0 0" size="500 500 0.125" type="plane" material="MatPlane" condim="3" conaffinity="1" contype="1" group="2" rgba="0.8 0.9 0.8 1"></geom>                                                                                                                                                      
    <light cutoff="100" diffuse="1 1 1" dir="-0 0 -1.3" directional="true" exponent="1" pos="0 0 1.3" specular=".1 .1 .1" castshadow="false"/>  
    <body name="pelvis" pos="0 0 0.45" childclass="nix1">
      <inertial pos="-0.0009 0 -0.0004" quat="0.498303 0.499454 -0.500496 0.501741" mass="1.616" diaginertia="0.002888289 0.002801285 0.001442911" />
      <joint name="floating_base_joint" type="free" limited="false" actuatorfrclimited="false"/>
      <site name='imu' size='0.01' pos='0.0 0 0.0'/>
      <geom type="mesh" contype="0" conaffinity="0" group="1" density="0" rgba="1 1 1 1" mesh="pelvis"/>
      <geom size="0.03987 0.047687 0.05" pos="-0.00493 0 -0.007691" type="box" rgba="1 1 1 1"/>
      <body name="left_hip_pitch_link" pos="0 0.0605 0">
        <inertial pos="-0.0005 0.0428 0.0007" quat="0.700543 0.695235 -0.102658 0.123892" mass="0.766" diaginertia="0.000524375 0.000513699 0.000467932"/>
        <joint name="left_hip_pitch_joint" pos="0 0 0" axis="0 1 0" range="-1.6755 1.5708" actuatorfrcrange="-102 102"/>
        <geom type="mesh" contype="0" conaffinity="0" group="1" density="0" rgba="1 1 1 1" mesh="left_hip_pitch_link"/>
        <geom size="0.042 0.05" pos="-0.005 0.044758 0" quat="0.707388 0 0.706825 0" type="cylinder" rgba="1 1 1 1"/>
        <body name="left_hip_roll_link" pos="0 0.044758 0">
          <inertial pos="-0.003 -0.0001 -0.0605" quat="0.705352 0.0541775 0.0650113 0.703787" mass="0.991" diaginertia="0.00174691 0.00141266 0.00115307"/>
          <joint name="left_hip_roll_joint" pos="0 0 0" axis="1 0 0" range="-0.0873 1.8326" actuatorfrcrange="-102 102"/>
          <geom type="mesh" contype="0" conaffinity="0" group="1" density="0" rgba="0.698039 0.698039 0.698039 1" mesh="left_hip_roll_link"/>
          <geom size="0.052 0.0406 0.025" pos="-0.005435 0 -0.071586" type="box" rgba="0.698039 0.698039 0.698039 1"/>
          <body name="left_hip_yaw_link" pos="-0.0037584 0 -0.104">
            <inertial pos="0.012 0.0025 -0.0415" quat="0.99212 0.0541072 -0.100631 0.0514188" mass="0.372" diaginertia="0.000817352 0.000723994 0.000543278"/>
            <joint name="left_hip_yaw_joint" pos="0 0 0" axis="0 0 1" range="-1.2217 2.0944" actuatorfrcrange="-102 102"/>
            <geom type="mesh" contype="0" conaffinity="0" group="1" density="0" rgba="0.698039 0.698039 0.698039 1" mesh="left_hip_yaw_link"/>
            <geom size="0.0476 0.0406 0.0535" pos="0.00074 0 -0.053493" type="box" rgba="0.698039 0.698039 0.698039 1"/>
            <body name="left_knee_link" pos="0 0 -0.0915">
              <inertial pos="-0.002 -0.0017 -0.071" quat="0.954805 -0.0103282 0.0427256 0.293964" mass="1.984" diaginertia="0.00906586 0.00900681 0.00154312"/>
              <joint name="left_knee_joint" pos="0 0 0" axis="0 1 0" range="-0.0873 2.1817" actuatorfrcrange="-102 102"/>
              <geom type="mesh" contype="0" conaffinity="0" group="1" density="0" rgba="0.698039 0.698039 0.698039 1" mesh="left_knee_link"/>
              <geom size="0.0456 0.04 0.074" pos="0.002367 0 -0.095618" type="box" rgba="0.698039 0.698039 0.698039 1"/>
              <body name="left_ankle_pitch_link" pos="-0.011569 -0.0005 -0.19979">
                <inertial pos="0.0085 0.0004 0" quat="-0.0766542 0.702957 0.0766487 0.702923" mass="0.086" diaginertia="4.2485e-05 2.58829e-05 2.17301e-05"/>
                <joint name="left_ankle_pitch_joint" pos="0 0 0" axis="0 1 0" range="-0.6109 0.6109" actuatorfrcrange="-20 20"/>
                <geom type="mesh" contype="0" conaffinity="0" group="1" density="0" rgba="0.898039 0.917647 0.929412 1" mesh="left_ankle_pitch_link"/>
                <body name="left_ankle_roll_link">
                  <inertial pos="0.032 -0.0043 -0.027" quat="-0.00217603 0.711488 -0.00768513 0.702653" mass="0.375" diaginertia="0.00143696 0.00123234 0.000301064"/>
                  <joint name="left_ankle_roll_joint" pos="0 0 0" axis="1 0 0" range="-0.3491 0.3491" actuatorfrcrange="-20 20"/>
                  <geom type="mesh" contype="0" conaffinity="0" group="1" density="0" rgba="1 1 1 1" mesh="left_ankle_roll_link"/>
                  <geom size="0.024 0.05 0.008" pos="-0.038 -0.005 -0.036" type="box" rgba="1 1 1 1"/>
                  <geom size="0.045 0.05 0.008" pos="0.0885 -0.005 -0.036" type="box" rgba="1 1 1 1"/>
                </body>
              </body>
            </body>
          </body>
        </body>
      </body>
      <body name="right_hip_pitch_link" pos="0 -0.0605 0">
        <inertial pos="-0.0005 -0.043 0.0006" quat="0.680361 0.720983 -0.0912827 0.0946593" mass="0.766" diaginertia="0.00052361 0.000515688 0.000466312"/>
        <joint name="right_hip_pitch_joint" pos="0 0 0" axis="0 1 0" range="-1.6755 1.5708" actuatorfrcrange="-102 102"/>
        <geom type="mesh" contype="0" conaffinity="0" group="1" density="0" rgba="1 1 1 1" mesh="right_hip_pitch_link"/>
        <geom size="0.042 0.05" pos="-0.005 -0.044758 0" quat="0.707388 0 0.706825 0" type="cylinder" rgba="1 1 1 1"/>
        <body name="right_hip_roll_link" pos="0 -0.044758 0">
          <inertial pos="-0.003 0.0002 -0.0605" quat="0.704527 0.0660932 0.0575429 0.704246" mass="0.991" diaginertia="0.00174679 0.00141323 0.00115244"/>
          <joint name="right_hip_roll_joint" pos="0 0 0" axis="1 0 0" range="-1.8326 0.0873" actuatorfrcrange="-102 102"/>
          <geom type="mesh" contype="0" conaffinity="0" group="1" density="0" rgba="0.698039 0.698039 0.698039 1" mesh="right_hip_roll_link"/>
          <geom size="0.052 0.0406 0.025" pos="-0.005435 0 -0.071586" type="box" rgba="0.698039 0.698039 0.698039 1"/>
          <body name="right_hip_yaw_link" pos="-0.0037584 0 -0.104">
            <inertial pos="0.012 -0.0025 -0.0415" quat="0.997357 -0.0656326 -0.0112312 -0.0290671" mass="0.372" diaginertia="0.000806162 0.000724927 0.00055344"/>
            <joint name="right_hip_yaw_joint" pos="0 0 0" axis="0 0 1" range="-2.0944 1.2217" actuatorfrcrange="-102 102"/>
            <geom type="mesh" contype="0" conaffinity="0" group="1" density="0" rgba="1 1 1 1" mesh="right_hip_yaw_link"/>
            <geom size="0.0476 0.0406 0.0535" pos="0.00074 0 -0.053493" type="box" rgba="1 1 1 1"/>
            <body name="right_knee_link" pos="0 0 -0.0915">
              <inertial pos="-0.002 0.0017 -0.0711" quat="0.954112 0.010109 0.0426618 -0.296223" mass="1.984" diaginertia="0.00907601 0.00901424 0.00154006"/>
              <joint name="right_knee_joint" pos="0 0 0" axis="0 1 0" range="-0.0873 2.1817" actuatorfrcrange="-102 102"/>
              <geom type="mesh" contype="0" conaffinity="0" group="1" density="0" rgba="1 1 1 1" mesh="right_knee_link"/>
              <geom size="0.0456 0.04 0.074" pos="0.002367 0 -0.095618" type="box" rgba="1 1 1 1"/>
              <body name="right_ankle_pitch_link" pos="-0.011569 0.0005 -0.19979">
                <inertial pos="0.0085 -0.0004 0" quat="0.0767231 0.702881 -0.0766976 0.702986" mass="0.086" diaginertia="4.2484e-05 2.58843e-05 2.17297e-05"/>
                <joint name="right_ankle_pitch_joint" pos="0 0 0" axis="0 1 0" range="-0.6109 0.6109" actuatorfrcrange="-20 20"/>
                <geom type="mesh" contype="0" conaffinity="0" group="1" density="0" rgba="0.898039 0.917647 0.929412 1" mesh="right_ankle_pitch_link"/>
                <body name="right_ankle_roll_link">
                  <inertial pos="0.032 0.0043 -0.027" quat="0.00217684 0.711488 0.00768442 0.702653" mass="0.375" diaginertia="0.00143696 0.00123234 0.000301064"/>
                  <joint name="right_ankle_roll_joint" pos="0 0 0" axis="1 0 0" range="-0.3491 0.3491" actuatorfrcrange="-20 20"/>
                  <geom type="mesh" contype="0" conaffinity="0" group="1" density="0" rgba="1 1 1 1" mesh="right_ankle_roll_link"/>
                  <geom size="0.024 0.05 0.008" pos="-0.038 0.005 -0.036" type="box" rgba="1 1 1 1"/>
                  <geom size="0.045 0.05 0.008" pos="0.0885 0.005 -0.036" type="box" rgba="1 1 1 1"/>
                </body>
              </body>
            </body>
          </body>
        </body>
      </body>
      <body name="torso_link" pos="0 0 0.24776">
        <inertial pos="-0.0103 0 -0.0419" quat="0.999601 0.000658299 -0.0275934 0.00600553" mass="6.618" diaginertia="0.0636973 0.0556223 0.0316944"/>
        <joint name="torso_joint" pos="0 0 0" axis="0 0 1" range="-1.5708 1.5708" actuatorfrcrange="-102 102"/>
        <geom type="mesh" contype="0" conaffinity="0" group="1" density="0" rgba="0.752941 0.752941 0.752941 1" mesh="torso_link"/>
        <geom size="0.082 0.0745 0.124" pos="0 0 -0.064322" type="box" rgba="0.752941 0.752941 0.752941 1"/>
        <geom size="0.0095 0.054 0.0095" pos="-0.116106 0 0.062336" quat="0.923189 0 0.384347 0" type="box" rgba="0.752941 0.752941 0.752941 1"/>
        <geom size="0.075" pos="0 0 0.13" type="sphere" rgba="0.752941 0.752941 0.752941 1"/>
        <body name="left_shoulder_pitch_link" pos="0 0.119 0" quat="0.999048 0.0436192 0 0">
          <inertial pos="-0.0005 0.0423 0.0007" quat="0.70055 0.695228 -0.102658 0.123894" mass="0.766" diaginertia="0.000524375 0.000513699 0.000467932"/>
          <joint name="left_shoulder_pitch_joint" pos="0 0 0" axis="0 1 0" range="-2.7925 2.7925" actuatorfrcrange="-102 102"/>
          <geom type="mesh" contype="0" conaffinity="0" group="1" density="0" rgba="1 1 1 1" mesh="left_shoulder_pitch_link"/>
          <geom size="0.042 0.05" pos="-0.005 0.044258 0" quat="0.707388 0 0.706825 0" type="cylinder" rgba="1 1 1 1"/>
          <body name="left_shoulder_roll_link" pos="0 0.044258 0" quat="0.999048 -0.0436192 0 0">
            <inertial pos="-0.003 -0.0001 -0.0602" quat="0.704614 0.0644388 0.0750035 0.702667" mass="0.995" diaginertia="0.00176915 0.00143202 0.00115692"/>
            <joint name="left_shoulder_roll_joint" pos="0 0 0" axis="1 0 0" range="0 1.9199" actuatorfrcrange="-102 102"/>
            <geom type="mesh" contype="0" conaffinity="0" group="1" density="0" rgba="0.698039 0.698039 0.698039 1" mesh="left_shoulder_roll_link"/>
            <geom size="0.052 0.0406 0.025" pos="-0.005435 0 -0.071586" type="box" rgba="0.698039 0.698039 0.698039 1"/>
            <body name="left_shoulder_yaw_link" pos="-0.0037584 0 -0.104">
              <inertial pos="-0.0001 0.0011 -0.0404" quat="0.69664 0.00905253 -0.0165216 0.717174" mass="0.855" diaginertia="0.000672099 0.000625484 0.000594466"/>
              <joint name="left_shoulder_yaw_joint" pos="0 0 0" axis="0 0 1" range="-1.885 1.885" actuatorfrcrange="-102 102"/>
              <geom type="mesh" contype="0" conaffinity="0" group="1" density="0" rgba="0.698039 0.698039 0.698039 1" mesh="left_shoulder_yaw_link"/>
              <body name="left_elbow_link" pos="0 0 -0.041258" quat="0.707105 0 -0.707108 0">
                <inertial pos="-0.0095 -0.0035 -0.04" quat="0.992388 0.0328768 -0.100534 0.0630765" mass="0.353" diaginertia="0.000999063 0.000908555 0.000468876"/>
                <joint name="left_elbow_joint" pos="0 0 0" axis="0 1 0" range="0 1.5708" actuatorfrcrange="-102 102"/>
                <geom type="mesh" contype="0" conaffinity="0" group="1" density="0" rgba="0.698039 0.698039 0.698039 1" mesh="left_elbow_link"/>
                <geom size="0.03165 0.0435 0.045" pos="-0.0205 -0.000342 -0.005649" type="box" rgba="0.698039 0.698039 0.698039 1"/>
                <geom size="0.0285 0.04905" pos="0 -0.000342 -0.101629" type="cylinder" rgba="0.698039 0.698039 0.698039 1"/>
              </body>
            </body>
          </body>
        </body>
        <body name="right_shoulder_pitch_link" pos="0 -0.119 0" quat="0.999048 -0.0436192 0 0">
          <inertial pos="-0.0005 -0.042 0.0006" quat="0.680353 0.72099 -0.0912841 0.0946593" mass="0.766" diaginertia="0.00052361 0.000515688 0.000466312"/>
          <joint name="right_shoulder_pitch_joint" pos="0 0 0" axis="0 1 0" range="-2.7925 2.7925" actuatorfrcrange="-102 102"/>
          <geom type="mesh" contype="0" conaffinity="0" group="1" density="0" rgba="1 1 1 1" mesh="right_shoulder_pitch_link"/>
          <geom size="0.042 0.05" pos="-0.005 -0.044258 0" quat="0.707388 0 0.706825 0" type="cylinder" rgba="1 1 1 1"/>
          <body name="right_shoulder_roll_link" pos="0 -0.044258 0" quat="0.999048 0.0436192 0 0">
            <inertial pos="-0.003 0.0002 -0.0602" quat="0.703443 0.0759294 0.0675605 0.703447" mass="0.995" diaginertia="0.00176901 0.00143267 0.00115619"/>
            <joint name="right_shoulder_roll_joint" pos="0 0 0" axis="1 0 0" range="-1.9199 0" actuatorfrcrange="-102 102"/>
            <geom type="mesh" contype="0" conaffinity="0" group="1" density="0" rgba="0.698039 0.698039 0.698039 1" mesh="right_shoulder_roll_link"/>
            <geom size="0.052 0.0406 0.025" pos="-0.005435 0 -0.071586" type="box" rgba="0.698039 0.698039 0.698039 1"/>
            <body name="right_shoulder_yaw_link" pos="-0.0037584 0 -0.104">
              <inertial pos="-0.0002 -0.0011 -0.0405" quat="0.709735 -0.000464656 0.0453815 0.703006" mass="0.855" diaginertia="0.000672372 0.000624176 0.000595679"/>
              <joint name="right_shoulder_yaw_joint" pos="0 0 0" axis="0 0 1" range="-1.885 1.885" actuatorfrcrange="-102 102"/>
              <geom type="mesh" contype="0" conaffinity="0" group="1" density="0" rgba="0.698039 0.698039 0.698039 1" mesh="right_shoulder_yaw_link"/>
              <body name="right_elbow_link" pos="0 0 -0.041258" quat="0.707105 0 -0.707108 0">
                <inertial pos="-0.0095 0.0035 -0.04" quat="0.992388 -0.0328751 -0.100534 -0.0630804" mass="0.353" diaginertia="0.000999063 0.000908555 0.000468876"/>
                <joint name="right_elbow_joint" pos="0 0 0" axis="0 1 0" range="0 1.5708" actuatorfrcrange="-102 102"/>
                <geom type="mesh" contype="0" conaffinity="0" group="1" density="0" rgba="1 1 1 1" mesh="right_elbow_link"/>
                <geom size="0.03165 0.0435 0.045" pos="-0.0205 0.000342 -0.005649" type="box" rgba="1 1 1 1"/>
                <geom size="0.0285 0.04905" pos="0 0.000342 -0.101629" type="cylinder" rgba="1 1 1 1"/>
              </body>
            </body>
          </body>
        </body>
      </body>
    </body>
  </worldbody>
  <actuator>
    <motor name="left_hip_pitch_joint" joint="left_hip_pitch_joint" gear="1" ctrllimited="true" ctrlrange="-100 100"/>
    <motor name="left_hip_roll_joint" joint="left_hip_roll_joint" gear="1" ctrllimited="true" ctrlrange="-100 100"/>
    <motor name="left_hip_yaw_joint" joint="left_hip_yaw_joint" gear="1" ctrllimited="true" ctrlrange="-100 100" />
    <motor name="left_knee_joint" joint="left_knee_joint" gear="1" ctrllimited="true" ctrlrange="-100 100"/>
    <motor name="left_ankle_pitch_joint" joint="left_ankle_pitch_joint" gear="1" ctrllimited="true" ctrlrange="-100 100"/>
    <motor name="left_ankle_roll_joint" joint="left_ankle_roll_joint" gear="1" ctrllimited="true" ctrlrange="-100 100"/>

    <motor name="right_hip_pitch_joint" joint="right_hip_pitch_joint" gear="1" ctrllimited="true" ctrlrange="-100 100"/>
    <motor name="right_hip_roll_joint" joint="right_hip_roll_joint" gear="1" ctrllimited="true" ctrlrange="-100 100"/>
    <motor name="right_hip_yaw_joint" joint="right_hip_yaw_joint" gear="1" ctrllimited="true" ctrlrange="-100 100"/>
    <motor name="right_knee_joint" joint="right_knee_joint" gear="1" ctrllimited="true" ctrlrange="-100 100" />
    <motor name="right_ankle_pitch_joint" joint="right_ankle_pitch_joint" gear="1" ctrllimited="true" ctrlrange="-100 100" />
    <motor name="right_ankle_roll_joint" joint="right_ankle_roll_joint" gear="1" ctrllimited="true" ctrlrange="-100 100" />

    <motor name="torso_joint" joint="torso_joint" gear="1" ctrllimited="true" ctrlrange="-100 100" /> 

    <motor name="left_shoulder_pitch_joint" joint="left_shoulder_pitch_joint" gear="1" ctrllimited="true" ctrlrange="-100 100" />
    <motor name="left_shoulder_roll_joint" joint="left_shoulder_roll_joint" gear="1" ctrllimited="true" ctrlrange="-100 100" />
    <motor name="left_shoulder_yaw_joint" joint="left_shoulder_yaw_joint" gear="1" ctrllimited="true" ctrlrange="-100 100" />
    <motor name="left_elbow_joint" joint="left_elbow_joint" gear="1" ctrllimited="true" ctrlrange="-100 100" />

    <motor name="right_shoulder_pitch_joint" joint="right_shoulder_pitch_joint" gear="1" ctrllimited="true" ctrlrange="-100 100" />
    <motor name="right_shoulder_roll_joint" joint="right_shoulder_roll_joint" gear="1" ctrllimited="true" ctrlrange="-100 100" />
    <motor name="right_shoulder_yaw_joint" joint="right_shoulder_yaw_joint" gear="1" ctrllimited="true" ctrlrange="-100 100" />
    <motor name="right_elbow_joint" joint="right_elbow_joint" gear="1" ctrllimited="true" ctrlrange="-100 100" />
  </actuator>

  <sensor>
    <framequat     name='orientation' objtype='site' noise='0.001' objname='imu'/>
    <framepos     name='position' objtype='site' noise='0.001' objname='imu'/>
    <gyro          name='angular-velocity'    site='imu' noise='0.005' cutoff='34.9'/>
    <velocimeter   name='linear-velocity'     site='imu' noise='0.001' cutoff='30'/>
    <accelerometer name='linear-acceleration' site='imu' noise='0.005' cutoff='157'/>
    <magnetometer  name='magnetometer'        site='imu'/>


    <jointactuatorfrc name="left_hip_pitch_force" joint="left_hip_pitch_joint"/>
    <jointactuatorfrc name="left_hip_roll_force" joint="left_hip_roll_joint"/>
    <jointactuatorfrc name="left_hip_yaw_force" joint="left_hip_yaw_joint"/>
    <jointactuatorfrc name="left_knee_force" joint="left_knee_joint"/>
    <jointactuatorfrc name="left_ankle_pitch_force" joint="left_ankle_pitch_joint"/>
    <jointactuatorfrc name="left_ankle_roll_force" joint="left_ankle_roll_joint"/>

    <jointactuatorfrc name="right_hip_pitch_force" joint="right_hip_pitch_joint"/>
    <jointactuatorfrc name="right_hip_roll_force" joint="right_hip_roll_joint"/>
    <jointactuatorfrc name="right_hip_yaw_force" joint="right_hip_yaw_joint"/>
    <jointactuatorfrc name="right_knee_force" joint="right_knee_joint"/>
    <jointactuatorfrc name="right_ankle_pitch_force" joint="right_ankle_pitch_joint"/>
    <jointactuatorfrc name="right_ankle_roll_force" joint="right_ankle_roll_joint"/>

    <jointactuatorfrc name="torso_force" joint="torso_joint"/>

    <jointactuatorfrc name="left_shoulder_pitch_force" joint="left_shoulder_pitch_joint"/>
    <jointactuatorfrc name="left_shoulder_roll_force" joint="left_shoulder_roll_joint"/>
    <jointactuatorfrc name="left_shoulder_yaw_force" joint="left_shoulder_yaw_joint"/>
    <jointactuatorfrc name="left_elbow_force" joint="left_elbow_joint"/>

    <jointactuatorfrc name="right_shoulder_pitch_force" joint="right_shoulder_pitch_joint"/>
    <jointactuatorfrc name="right_shoulder_roll_force" joint="right_shoulder_roll_joint"/>
    <jointactuatorfrc name="right_shoulder_yaw_force" joint="right_shoulder_yaw_joint"/>
    <jointactuatorfrc name="right_elbow_force" joint="right_elbow_joint"/>
  </sensor>
</mujoco>
